Workbook

Sheet Rough Notes
A1: System | B1: Observe | C1: Orient | D1: Decide | E1: Act
A3: Crewmember #1 | B3: Physical location | C3: Assess viability of mission | D3: Follow path | E3: 1. Drive LTV
B4: Health status (SE) | D4: Conduct science experiment | E4: 2. Transport cargo | G4: RQ 1 Structural
D5: Proceed or abort mission | G5: CHANGE # CREW MEMBERS from 2 to 3
G6: LTV AUTONOMY LEVEL CONFIGURATIONS
G7: LTV AUTONOMY AUTHORITY SWAP
A8: Crewmember #2 | B8: Physical location | C8: Assess viability of mission | D8: Follow path | E8: Deploy science equipment
B9: Health status (SE) | D9: Conduct science experiment | E9: Transport cargo | G9: RQ 2 Tuning
D10: Proceed or abort mission | G10: At higher autonomy levels
A11: LTV | B11: Physical location Vehicle health | C11: Route planning | E11: Transport crew members and science equipment | G11: Fine-Tune autonomy parameters at higher levels
E12: Crew life support
A13: HLS | B13: Receive crew health data | C13: Transmit data to Ground Control | E13: Crew support and safety
B14: Monitor system health | C14: Transmit data to crew
A15: Ground Control | B15: Crew health | C15: Mission coordination | D15: Mission guidance | E15: Support crew transport to/from Moon
B16: System status | C16: Navigation | D16: Emergency protocols
B17: Location
B18: Debris management
A19: Science Equipment | E19: Sample collection

Sheet Default Network Metrics
A1: THIS SHEET IS REFERENCED; CHANGE WITH CAUTION
A2: SOD | AA2: SOURCE | AC2: Self Effectiveness (80% base)
B3: 0 | C3: 0.9 | D3: 0 | E3: 0 | F3: 0 | G3: 0 | H3: 0 | I3: 0 | J3: 0 | K3: 0 | L3: 0 | M3: 0 | N3: 0 | O3: 0 | P3: 0 | Q3: 0 | R3: 1 | S3: 0 | T3: 0 | U3: 0 | V3: 0 | W3: 0 | X3: 0 | Y3: 0 | AA3: Crew1_Obs | AC3: B | AD3: 5 | AE3: 2
B4: 0 | C4: 0 | D4: 0.9 | E4: 0 | F4: 0 | G4: 0 | H4: 0 | I4: 0 | J4: 0 | K4: 0 | L4: 0 | M4: 0 | N4: 0 | O4: 0 | P4: 0 | Q4: 0 | R4: 0 | S4: 0 | T4: 0 | U4: 0 | V4: 0 | W4: 0 | X4: 0 | Y4: 0 | AA4: Crew1_Ori | AC4: B | AD4: 5 | AE4: 2
B5: 0 | C5: 0 | D5: 0 | E5: 0.9 | F5: 0 | G5: 0 | H5: 0 | I5: 0 | J5: 0 | K5: 0 | L5: 0 | M5: 0 | N5: 0 | O5: 0 | P5: 0 | Q5: 0 | R5: 0 | S5: 0 | T5: 0 | U5: 0 | V5: 0 | W5: 0 | X5: 0 | Y5: 0.5 | AA5: Crew1_Dec | AC5: B | AD5: 5 | AE5: 2
B6: 0 | C6: 0 | D6: 0 | E6: 0 | F6: 0 | G6: 0 | H6: 0 | I6: 0 | J6: 0 | K6: 0 | L6: 0 | M6: 0 | N6: 0 | O6: 0 | P6: 0 | Q6: 0.9 | R6: 0 | S6: 0 | T6: 0 | U6: 0 | V6: 0 | W6: 0 | X6: 0 | Y6: 0 | AA6: Crew1_Act | AC6: B | AD6: 5 | AE6: 2
B7: 0 | C7: 0 | D7: 0 | E7: 0 | F7: 0 | G7: 0.9 | H7: 0 | I7: 0 | J7: 0 | K7: 0 | L7: 0 | M7: 0 | N7: 0 | O7: 0 | P7: 0 | Q7: 0 | R7: 1 | S7: 0 | T7: 0 | U7: 0 | V7: 0 | W7: 0 | X7: 0 | Y7: 0 | AA7: Crew2_Obs | AC7: B | AD7: 5 | AE7: 2
B8: 0 | C8: 0 | D8: 0 | E8: 0 | F8: 0 | G8: 0 | H8: 0.9 | I8: 0 | J8: 0 | K8: 0 | L8: 0 | M8: 0 | N8: 0 | O8: 0 | P8: 0 | Q8: 0 | R8: 0 | S8: 0 | T8: 0 | U8: 0 | V8: 0 | W8: 0 | X8: 0 | Y8: 0 | AA8: Crew2_Ori | AC8: B | AD8: 5 | AE8: 2
B9: 0 | C9: 0 | D9: 0 | E9: 0 | F9: 0 | G9: 0 | H9: 0 | I9: 0.9 | J9: 0 | K9: 0 | L9: 0 | M9: 0 | N9: 0 | O9: 0 | P9: 0 | Q9: 0 | R9: 0 | S9: 0 | T9: 0 | U9: 0 | V9: 0 | W9: 0 | X9: 0 | Y9: 0.5 | AA9: Crew2_Dec | AC9: B | AD9: 5 | AE9: 2
B10: 0 | C10: 0 | D10: 0 | E10: 0 | F10: 0 | G10: 0 | H10: 0 | I10: 0 | J10: 0 | K10: 0 | L10: 0 | M10: 0 | N10: 0 | O10: 0 | P10: 0 | Q10: 0 | R10: 0 | S10: 0 | T10: 0 | U10: 0 | V10: 0 | W10: 0 | X10: 0 | Y10: 0.9 | AA10: Crew2_Act | AC10: B | AD10: 5 | AE10: 2
B11: 0 | C11: 0 | D11: 0 | E11: 0 | F11: 0 | G11: 0 | H11: 0 | I11: 0 | J11: 0 | K11: 0 | L11: 0 | M11: 0 | N11: 0 | O11: 0 | P11: 0 | Q11: 0 | R11: 0 | S11: 0 | T11: 0 | U11: 0 | V11: 0 | W11: 0 | X11: 0 | Y11: 0 | AA11: Crew3_Obs | AC11: B | AD11: 0 | AE11: 0
B12: 0 | C12: 0 | D12: 0 | E12: 0 | F12: 0 | G12: 0 | H12: 0 | I12: 0 | J12: 0 | K12: 0 | L12: 0 | M12: 0 | N12: 0 | O12: 0 | P12: 0 | Q12: 0 | R12: 0 | S12: 0 | T12: 0 | U12: 0 | V12: 0 | W12: 0 | X12: 0 | Y12: 0 | AA12: Crew3_Ori | AC12: B | AD12: 0 | AE12: 0
B13: 0 | C13: 0 | D13: 0 | E13: 0 | F13: 0 | G13: 0 | H13: 0 | I13: 0 | J13: 0 | K13: 0 | L13: 0 | M13: 0 | N13: 0 | O13: 0 | P13: 0 | Q13: 0 | R13: 0 | S13: 0 | T13: 0 | U13: 0 | V13: 0 | W13: 0 | X13: 0 | Y13: 0 | AA13: Crew3_Dec | AC13: B | AD13: 0 | AE13: 0
B14: 0 | C14: 0 | D14: 0 | E14: 0 | F14: 0 | G14: 0 | H14: 0 | I14: 0 | J14: 0 | K14: 0 | L14: 0 | M14: 0 | N14: 0 | O14: 0 | P14: 0 | Q14: 0 | R14: 0 | S14: 0 | T14: 0 | U14: 0 | V14: 0 | W14: 0 | X14: 0 | Y14: 0 | AA14: Crew3_Act | AC14: B | AD14: 0 | AE14: 0
B15: 0 | C15: 0 | D15: 0 | E15: 0 | F15: 0 | G15: 0 | H15: 0 | I15: 0 | J15: 0 | K15: 0 | L15: 0 | M15: 0 | N15: 0 | O15: 0.9 | P15: 0 | Q15: 0 | R15: 0 | S15: 0 | T15: 0 | U15: 0 | V15: 0 | W15: 0 | X15: 0 | Y15: 0 | AA15: LTV_Obs | AC15: D | AD15: 80
B16: 0 | C16: 0 | D16: 0.5 | E16: 0 | F16: 0 | G16: 0 | H16: 0 | I16: 0 | J16: 0 | K16: 0 | L16: 0 | M16: 0 | N16: 0 | O16: 0 | P16: 0 | Q16: 0 | R16: 0 | S16: 0 | T16: 0 | U16: 0 | V16: 0 | W16: 0 | X16: 0 | Y16: 0 | AA16: LTV_Ori | AC16: D | AD16: 80
B17: 0 | C17: 0 | D17: 0 | E17: 0 | F17: 0 | G17: 0 | H17: 0 | I17: 0 | J17: 0 | K17: 0 | L17: 0 | M17: 0 | N17: 0 | O17: 0 | P17: 0 | Q17: 0 | R17: 0 | S17: 0 | T17: 0 | U17: 0 | V17: 0 | W17: 0 | X17: 0 | Y17: 0 | AA17: LTV_Dec | AC17: D | AD17: ='Event Register'!AI3 -> 0
B18: 0.8 | C18: 0 | D18: 0 | E18: 0 | F18: 0.8 | G18: 0 | H18: 0 | I18: 0 | J18: 0 | K18: 0 | L18: 0 | M18: 0 | N18: 0.9 | O18: 0 | P18: 0 | Q18: 0 | R18: 0 | S18: 0 | T18: 0 | U18: 0 | V18: 0 | W18: 0 | X18: 0 | Y18: 0.9 | AA18: LTV_Act | AC18: D | AD18: 80
B19: 0 | C19: 0 | D19: 0 | E19: 0 | F19: 0 | G19: 0 | H19: 0 | I19: 0 | J19: 0 | K19: 0 | L19: 0 | M19: 0 | N19: 0 | O19: 0 | P19: 0 | Q19: 0 | R19: 0 | S19: 0.9 | T19: 0 | U19: 0.5 | V19: 0 | W19: 0 | X19: 0 | Y19: 0 | AA19: HLS_Obs | AC19: D | AD19: 80
B20: 0.5 | C20: 0 | D20: 0 | E20: 0 | F20: 0.5 | G20: 0 | H20: 0 | I20: 0 | J20: 0 | K20: 0 | L20: 0 | M20: 0 | N20: 0 | O20: 0 | P20: 0 | Q20: 0 | R20: 0 | S20: 0 | T20: 0.9 | U20: 0.5 | V20: 0 | W20: 0 | X20: 0 | Y20: 0 | AA20: HLS_Ori | AC20: D | AD20: 80
B21: 0.2 | C21: 0 | D21: 0 | E21: 0 | F21: 0.2 | G21: 0 | H21: 0 | I21: 0 | J21: 0 | K21: 0 | L21: 0 | M21: 0 | N21: 0 | O21: 0 | P21: 0 | Q21: 0 | R21: 0 | S21: 0 | T21: 0 | U21: 0 | V21: 0 | W21: 0 | X21: 0 | Y21: 0 | AA21: HLS_Act | AC21: D | AD21: 80
B22: 0 | C22: 0 | D22: 0 | E22: 0 | F22: 0 | G22: 0 | H22: 0 | I22: 0 | J22: 0 | K22: 0 | L22: 0 | M22: 0 | N22: 0 | O22: 0 | P22: 0 | Q22: 0 | R22: 0 | S22: 0 | T22: 0 | U22: 0 | V22: 0.9 | W22: 0 | X22: 0 | Y22: 0 | AA22: GC_Obs | AC22: D | AD22: 80
B23: 0 | C23: 0 | D23: 0 | E23: 0 | F23: 0 | G23: 0 | H23: 0 | I23: 0 | J23: 0 | K23: 0 | L23: 0 | M23: 0 | N23: 0 | O23: 0 | P23: 0 | Q23: 0 | R23: 0 | S23: 0 | T23: 0 | U23: 0 | V23: 0 | W23: 0.9 | X23: 0 | Y23: 0 | AA23: GC_Ori | AC23: D | AD23: 80
B24: 0 | C24: 0 | D24: 0 | E24: 0 | F24: 0 | G24: 0 | H24: 0 | I24: 0 | J24: 0 | K24: 0 | L24: 0 | M24: 0 | N24: 0 | O24: 0 | P24: 0 | Q24: 0 | R24: 0 | S24: 0 | T24: 0 | U24: 0 | V24: 0 | W24: 0 | X24: 0.9 | Y24: 0 | AA24: GC_Dec | AC24: D | AD24: 80
B25: 0 | C25: 0 | D25: 0 | E25: 0 | F25: 0 | G25: 0 | H25: 0 | I25: 0 | J25: 0 | K25: 0 | L25: 0 | M25: 0 | N25: 0 | O25: 0 | P25: 0 | Q25: 0 | R25: 0 | S25: 0 | T25: 0 | U25: 0 | V25: 0 | W25: 0 | X25: 0 | Y25: 0 | AA25: GC_Act | AC25: D | AD25: 80
B26: 0 | C26: 0 | D26: 0 | E26: 0 | F26: 0 | G26: 0 | H26: 0 | I26: 0 | J26: 0 | K26: 0 | L26: 0 | M26: 0 | N26: 0 | O26: 0 | P26: 0 | Q26: 0 | R26: 0 | S26: 0 | T26: 0 | U26: 0 | V26: 0 | W26: 0 | X26: 0 | Y26: 0 | AA26: SciEq_Act | AC26: D | AD26: 80
A28: DESINTATION | B28: Crew1_Obs | C28: Crew1_Ori | D28: Crew1_Dec | E28: Crew1_Act | F28: Crew2_Obs | G28: Crew2_Ori | H28: Crew2_Dec | I28: Crew2_Act | J28: Crew3_Obs | K28: Crew3_Ori | L28: Crew3_Dec | M28: Crew3_Act | N28: LTV_Obs | O28: LTV_Ori | P28: LTV_Dec | Q28: LTV_Act | R28: HLS_Obs | S28: HLS_Ori | T28: HLS_Act | U28: GC_Obs | V28: GC_Ori | W28: GC_Dec | X28: GC_Act | Y28: SciEq_Act
A30: COD
B31: 0 | C31: 100 | D31: 0 | E31: 0 | F31: 0 | G31: 0 | H31: 0 | I31: 0 | J31: 0 | K31: 0 | L31: 0 | M31: 0 | N31: 0 | O31: 0 | P31: 0 | Q31: 0 | R31: 100 | S31: 0 | T31: 0 | U31: 0 | V31: 0 | W31: 0 | X31: 0 | Y31: 0 | AA31: Crew1_Obs
B32: 0 | C32: 0 | D32: 100 | E32: 0 | F32: 0 | G32: 0 | H32: 0 | I32: 0 | J32: 0 | K32: 0 | L32: 0 | M32: 0 | N32: 0 | O32: 0 | P32: 0 | Q32: 0 | R32: 0 | S32: 0 | T32: 0 | U32: 0 | V32: 0 | W32: 0 | X32: 0 | Y32: 0 | AA32: Crew1_Ori
B33: 0 | C33: 0 | D33: 0 | E33: 100 | F33: 0 | G33: 0 | H33: 0 | I33: 0 | J33: 0 | K33: 0 | L33: 0 | M33: 0 | N33: 0 | O33: 0 | P33: 0 | Q33: 0 | R33: 0 | S33: 0 | T33: 0 | U33: 0 | V33: 0 | W33: 0 | X33: 0 | Y33: 50 | AA33: Crew1_Dec
B34: 0 | C34: 0 | D34: 0 | E34: 0 | F34: 0 | G34: 0 | H34: 0 | I34: 0 | J34: 0 | K34: 0 | L34: 0 | M34: 0 | N34: 0 | O34: 0 | P34: 0 | Q34: 100 | R34: 0 | S34: 0 | T34: 0 | U34: 0 | V34: 0 | W34: 0 | X34: 0 | Y34: 0 | AA34: Crew1_Act
B35: 0 | C35: 0 | D35: 0 | E35: 0 | F35: 0 | G35: 100 | H35: 0 | I35: 0 | J35: 0 | K35: 0 | L35: 0 | M35: 0 | N35: 0 | O35: 0 | P35: 0 | Q35: 0 | R35: 100 | S35: 0 | T35: 0 | U35: 0 | V35: 0 | W35: 0 | X35: 0 | Y35: 0 | AA35: Crew2_Obs
B36: 0 | C36: 0 | D36: 0 | E36: 0 | F36: 0 | G36: 0 | H36: 100 | I36: 0 | J36: 0 | K36: 0 | L36: 0 | M36: 0 | N36: 0 | O36: 0 | P36: 0 | Q36: 0 | R36: 0 | S36: 0 | T36: 0 | U36: 0 | V36: 0 | W36: 0 | X36: 0 | Y36: 0 | AA36: Crew2_Ori
B37: 0 | C37: 0 | D37: 0 | E37: 0 | F37: 0 | G37: 0 | H37: 0 | I37: 100 | J37: 0 | K37: 0 | L37: 0 | M37: 0 | N37: 0 | O37: 0 | P37: 0 | Q37: 0 | R37: 0 | S37: 0 | T37: 0 | U37: 0 | V37: 0 | W37: 0 | X37: 0 | Y37: 50 | AA37: Crew2_Dec
B38: 0 | C38: 0 | D38: 0 | E38: 0 | F38: 0 | G38: 0 | H38: 0 | I38: 0 | J38: 0 | K38: 0 | L38: 0 | M38: 0 | N38: 0 | O38: 0 | P38: 0 | Q38: 0 | R38: 0 | S38: 0 | T38: 0 | U38: 0 | V38: 0 | W38: 0 | X38: 0 | Y38: 100 | AA38: Crew2_Act
B39: 0 | C39: 0 | D39: 0 | E39: 0 | F39: 0 | G39: 0 | H39: 0 | I39: 0 | J39: 0 | K39: 0 | L39: 0 | M39: 0 | N39: 0 | O39: 0 | P39: 0 | Q39: 0 | R39: 0 | S39: 0 | T39: 0 | U39: 0 | V39: 0 | W39: 0 | X39: 0 | Y39: 0 | AA39: Crew3_Obs
B40: 0 | C40: 0 | D40: 0 | E40: 0 | F40: 0 | G40: 0 | H40: 0 | I40: 0 | J40: 0 | K40: 0 | L40: 0 | M40: 0 | N40: 0 | O40: 0 | P40: 0 | Q40: 0 | R40: 0 | S40: 0 | T40: 0 | U40: 0 | V40: 0 | W40: 0 | X40: 0 | Y40: 0 | AA40: Crew3_Ori
B41: 0 | C41: 0 | D41: 0 | E41: 0 | F41: 0 | G41: 0 | H41: 0 | I41: 0 | J41: 0 | K41: 0 | L41: 0 | M41: 0 | N41: 0 | O41: 0 | P41: 0 | Q41: 0 | R41: 0 | S41: 0 | T41: 0 | U41: 0 | V41: 0 | W41: 0 | X41: 0 | Y41: 0 | AA41: Crew3_Dec
B42: 0 | C42: 0 | D42: 0 | E42: 0 | F42: 0 | G42: 0 | H42: 0 | I42: 0 | J42: 0 | K42: 0 | L42: 0 | M42: 0 | N42: 0 | O42: 0 | P42: 0 | Q42: 0 | R42: 0 | S42: 0 | T42: 0 | U42: 0 | V42: 0 | W42: 0 | X42: 0 | Y42: 0 | AA42: Crew3_Act
...

Sheet Event Register
A1: Network Event/Condition Group | B1: CONDITION SWITCH | C1: X% | D1: Metric Affected | E1: System(s) Affected [Edges: source | destination] | G1: Default Value (0%) | H1: Transient (X%) Value | I1: Switched Value | J1: Condition Applied (100%) Value | L1: THIS SHEET IS REFERENCED; CHANGE WITH CAUTION
A2: Add Crew #3 | B2: 1 | C2: 100 | D2: SE; alpha | E2: Crew3_Obs | G2: ='Default Network Metrics'!AD11 -> 0 | H2: =(1-($C$2/100))*G2+($C$2/100)*I2 -> 5 | I2: =J2*$B$2+G2*(1-$B$2) -> 5 | J2: 5
D3: SE; alpha | E3: Crew3_Ori | G3: ='Default Network Metrics'!AD12 -> 0 | H3: =(1-($C$2/100))*G3+($C$2/100)*I3 -> 5 | I3: =J3*$B$2+G3*(1-$B$2) -> 5 | J3: 5
D4: SE; alpha | E4: Crew3_Dec | G4: ='Default Network Metrics'!AD13 -> 0 | H4: =(1-($C$2/100))*G4+($C$2/100)*I4 -> 5 | I4: =J4*$B$2+G4*(1-$B$2) -> 5 | J4: 5
D5: SE; alpha | E5: Crew3_Act | G5: ='Default Network Metrics'!AD14 -> 0 | H5: =(1-($C$2/100))*G5+($C$2/100)*I5 -> 5 | I5: =J5*$B$2+G5*(1-$B$2) -> 5 | J5: 5
D6: SE; beta | E6: Crew3_Obs | G6: ='Default Network Metrics'!AE11 -> 0 | H6: =(1-($C$2/100))*G6+($C$2/100)*I6 -> 2 | I6: =J6*$B$2+G6*(1-$B$2) -> 2 | J6: 2
D7: SE; beta | E7: Crew3_Ori | G7: ='Default Network Metrics'!AE12 -> 0 | H7: =(1-($C$2/100))*G7+($C$2/100)*I7 -> 2 | I7: =J7*$B$2+G7*(1-$B$2) -> 2 | J7: 2
D8: SE; beta | E8: Crew3_Dec | G8: ='Default Network Metrics'!AE13 -> 0 | H8: =(1-($C$2/100))*G8+($C$2/100)*I8 -> 2 | I8: =J8*$B$2+G8*(1-$B$2) -> 2 | J8: 2
D9: SE; beta | E9: Crew3_Act | G9: ='Default Network Metrics'!AE14 -> 0 | H9: =(1-($C$2/100))*G9+($C$2/100)*I9 -> 2 | I9: =J9*$B$2+G9*(1-$B$2) -> 2 | J9: 2
D10: SOD | E10: Crew3_Obs | F10: Crew3_Ori | G10: ='Default Network Metrics'!K11 -> 0 | H10: =(1-($C$2/100))*G10+($C$2/100)*I10 -> 0.9 | I10: =J10*$B$2+G10*(1-$B$2) -> 0.9 | J10: 0.9
D11: COD | E11: Crew3_Obs | F11: Crew3_Ori | G11: ='Default Network Metrics'!K39 -> 0 | H11: =(1-($C$2/100))*G11+($C$2/100)*I11 -> 100 | I11: =J11*$B$2+G11*(1-$B$2) -> 100 | J11: 100
D12: IOD | E12: Crew3_Obs | F12: Crew3_Ori | G12: ='Default Network Metrics'!K67 -> 0 | H12: =(1-($C$2/100))*G12+($C$2/100)*I12 -> 90 | I12: =J12*$B$2+G12*(1-$B$2) -> 90 | J12: 90
D13: SOD | E13: Crew3_Ori | F13: Crew3_Dec | G13: ='Default Network Metrics'!L12 -> 0 | H13: =(1-($C$2/100))*G13+($C$2/100)*I13 -> 0.9 | I13: =J13*$B$2+G13*(1-$B$2) -> 0.9 | J13: 0.9
D14: COD | E14: Crew3_Ori | F14: Crew3_Dec | G14: ='Default Network Metrics'!L40 -> 0 | H14: =(1-($C$2/100))*G14+($C$2/100)*I14 -> 100 | I14: =J14*$B$2+G14*(1-$B$2) -> 100 | J14: 100
D15: IOD | E15: Crew3_Ori | F15: Crew3_Dec | G15: ='Default Network Metrics'!L68 -> 0 | H15: =(1-($C$2/100))*G15+($C$2/100)*I15 -> 90 | I15: =J15*$B$2+G15*(1-$B$2) -> 90 | J15: 90
D16: SOD | E16: Crew3_Dec | F16: Crew3_Act | G16: ='Default Network Metrics'!M13 -> 0 | H16: =(1-($C$2/100))*G16+($C$2/100)*I16 -> 0.9 | I16: =J16*$B$2+G16*(1-$B$2) -> 0.9 | J16: 0.9
D17: COD | E17: Crew3_Dec | F17: Crew3_Act | G17: ='Default Network Metrics'!M41 -> 0 | H17: =(1-($C$2/100))*G17+($C$2/100)*I17 -> 100 | I17: =J17*$B$2+G17*(1-$B$2) -> 100 | J17: 100
D18: IOD | E18: Crew3_Dec | F18: Crew3_Act | G18: ='Default Network Metrics'!M69 -> 0 | H18: =(1-($C$2/100))*G18+($C$2/100)*I18 -> 90 | I18: =J18*$B$2+G18*(1-$B$2) -> 90 | J18: 90
D19: SOD | E19: Crew3_Obs | F19: HLS_Obs | G19: ='Default Network Metrics'!R11 -> 0 | H19: =(1-($C$2/100))*G19+($C$2/100)*I19 -> 1 | I19: =J19*$B$2+G19*(1-$B$2) -> 1 | J19: 1
D20: COD | E20: Crew3_Obs | F20: HLS_Obs | G20: ='Default Network Metrics'!R39 -> 0 | H20: =(1-($C$2/100))*G20+($C$2/100)*I20 -> 100 | I20: =J20*$B$2+G20*(1-$B$2) -> 100 | J20: 100
D21: IOD | E21: Crew3_Obs | F21: HLS_Obs | G21: ='Default Network Metrics'!R67 -> 0 | H21: =(1-($C$2/100))*G21+($C$2/100)*I21 -> 10 | I21: =J21*$B$2+G21*(1-$B$2) -> 10 | J21: 10
D22: SOD | E22: Crew3_Dec | F22: Sci_EqAct | G22: ='Default Network Metrics'!Y13 -> 0 | H22: =(1-($C$2/100))*G22+($C$2/100)*I22 -> 0.5 | I22: =J22*$B$2+G22*(1-$B$2) -> 0.5 | J22: 0.5
D23: COD | E23: Crew3_Dec | F23: Sci_EqAct | G23: ='Default Network Metrics'!Y41 -> 0 | H23: =(1-($C$2/100))*G23+($C$2/100)*I23 -> 50 | I23: =J23*$B$2+G23*(1-$B$2) -> 50 | J23: 50
D24: IOD | E24: Crew3_Dec | F24: Sci_EqAct | G24: ='Default Network Metrics'!Y69 -> 0 | H24: =(1-($C$2/100))*G24+($C$2/100)*I24 -> 50 | I24: =J24*$B$2+G24*(1-$B$2) -> 50 | J24: 50
D25: SOD | E25: Crew3_Act | F25: Sci_EqAct | G25: ='Default Network Metrics'!Y14 -> 0 | H25: =(1-($C$2/100))*G25+($C$2/100)*I25 -> 0.9 | I25: =J25*$B$2+G25*(1-$B$2) -> 0.9 | J25: 0.9
D26: COD | E26: Crew3_Act | F26: Sci_EqAct | G26: ='Default Network Metrics'!Y42 -> 0 | H26: =(1-($C$2/100))*G26+($C$2/100)*I26 -> 100 | I26: =J26*$B$2+G26*(1-$B$2) -> 100 | J26: 100
D27: IOD | E27: Crew3_Act | F27: Sci_EqAct | G27: ='Default Network Metrics'!Y70 -> 0 | H27: =(1-($C$2/100))*G27+($C$2/100)*I27 -> 100 | I27: =J27*$B$2+G27*(1-$B$2) -> 100 | J27: 100
D28: SOD | E28: LTV_Act | F28: Crew3_Obs | G28: ='Default Network Metrics'!J18 -> 0 | H28: =(1-($C$2/100))*G28+($C$2/100)*I28 -> 0.8 | I28: =J28*$B$2+G28*(1-$B$2) -> 0.8 | J28: 0.8
D29: COD | E29: LTV_Act | F29: Crew3_Obs | G29: ='Default Network Metrics'!J46 -> 0 | H29: =(1-($C$2/100))*G29+($C$2/100)*I29 -> 90 | I29: =J29*$B$2+G29*(1-$B$2) -> 90 | J29: 90
D30: IOD | E30: LTV_Act | F30: Crew3_Obs | G30: ='Default Network Metrics'!J74 -> 0 | H30: =(1-($C$2/100))*G30+($C$2/100)*I30 -> 90 | I30: =J30*$B$2+G30*(1-$B$2) -> 90 | J30: 90
D31: SOD | E31: HLS_Ori | F31: Crew3_Obs | G31: ='Default Network Metrics'!J20 -> 0 | H31: =(1-($C$2/100))*G31+($C$2/100)*I31 -> 0.5 | I31: =J31*$B$2+G31*(1-$B$2) -> 0.5 | J31: 0.5
D32: COD | E32: HLS_Ori | F32: Crew3_Obs | G32: ='Default Network Metrics'!J48 -> 0 | H32: =(1-($C$2/100))*G32+($C$2/100)*I32 -> 80 | I32: =J32*$B$2+G32*(1-$B$2) -> 80 | J32: 80
D33: IOD | E33: HLS_Ori | F33: Crew3_Obs | G33: ='Default Network Metrics'!J76 -> 0 | H33: =(1-($C$2/100))*G33+($C$2/100)*I33 -> 50 | I33: =J33*$B$2+G33*(1-$B$2) -> 50 | J33: 50
D34: SOD | E34: HLS_Act | F34: Crew3_Obs | G34: ='Default Network Metrics'!J21 -> 0 | H34: =(1-($C$2/100))*G34+($C$2/100)*I34 -> 0.2 | I34: =J34*$B$2+G34*(1-$B$2) -> 0.2 | J34: 0.2
D35: COD | E35: HLS_Act | F35: Crew3_Obs | G35: ='Default Network Metrics'!J49 -> 0 | H35: =(1-($C$2/100))*G35+($C$2/100)*I35 -> 50 | I35: =J35*$B$2+G35*(1-$B$2) -> 50 | J35: 50
D36: IOD | E36: HLS_Act | F36: Crew3_Obs | G36: ='Default Network Metrics'!J77 -> 0 | H36: =(1-($C$2/100))*G36+($C$2/100)*I36 -> 50 | I36: =J36*$B$2+G36*(1-$B$2) -> 50 | J36: 50
A37: LTV Autonomy (FA) | B37: 0 | C37: 100 | D37: SE; value | E37: LTV_Dec | G37: ='Default Network Metrics'!AD17 -> 0 | H37: =(1-($C$37/100))*G37+($C$37/100)*I37 -> 0 | I37: =J37*$B$37+G37*(1-$B$37) -> 0 | J37: 80
D38: SOD | E38: LTV_Ori | F38: LTV_Dec | G38: ='Default Network Metrics'!P16 -> 0 | H38: =(1-($C$37/100))*G38+($C$37/100)*I38 -> 0 | I38: =J38*$B$37+G38*(1-$B$37) -> 0 | J38: 0.9
D39: COD | E39: LTV_Ori | F39: LTV_Dec | G39: ='Default Network Metrics'!P44 -> 0 | H39: =(1-($C$37/100))*G39+($C$37/100)*I39 -> 0 | I39: =J39*$B$37+G39*(1-$B$37) -> 0 | J39: 100
D40: IOD | E40: LTV_Ori | F40: LTV_Dec | G40: ='Default Network Metrics'!P72 -> 0 | H40: =(1-($C$37/100))*G40+($C$37/100)*I40 -> 0 | I40: =J40*$B$37+G40*(1-$B$37) -> 0 | J40: 90
...

Sheet n
A1: 24

Sheet SOD
A1: ='Default Network Metrics'!B3 -> 0 | B1: ='Default Network Metrics'!C3 -> 0.9 | C1: ='Default Network Metrics'!D3 -> 0 | D1: ='Default Network Metrics'!E3 -> 0 | E1: ='Default Network Metrics'!F3 -> 0 | F1: ='Default Network Metrics'!G3 -> 0 | G1: ='Default Network Metrics'!H3 -> 0 | H1: ='Default Network Metrics'!I3 -> 0 | ... X1: ='Default Network Metrics'!Y3 -> 0
A2: ='Default Network Metrics'!B4 -> 0 | B2: ='Default Network Metrics'!C4 -> 0 | C2: ='Default Network Metrics'!D4 -> 0.9 | D2: ='Default Network Metrics'!E4 -> 0 | E2: ='Default Network Metrics'!F4 -> 0 | F2: ='Default Network Metrics'!G4 -> 0 | G2: ='Default Network Metrics'!H4 -> 0 | H2: ='Default Network Metrics'!I4 -> 0 | ... X2: ='Default Network Metrics'!Y4 -> 0
A3: ='Default Network Metrics'!B5 -> 0 | B3: ='Default Network Metrics'!C5 -> 0 | C3: ='Default Network Metrics'!D5 -> 0 | D3: ='Default Network Metrics'!E5 -> 0.9 | E3: ='Default Network Metrics'!F5 -> 0 | F3: ='Default Network Metrics'!G5 -> 0 | G3: ='Default Network Metrics'!H5 -> 0 | H3: ='Default Network Metrics'!I5 -> 0 | ... X3: ='Default Network Metrics'!Y5 -> 0.5
A4: ='Default Network Metrics'!B6 -> 0 | B4: ='Default Network Metrics'!C6 -> 0 | C4: ='Default Network Metrics'!D6 -> 0 | D4: ='Default Network Metrics'!E6 -> 0 | E4: ='Default Network Metrics'!F6 -> 0 | F4: ='Default Network Metrics'!G6 -> 0 | G4: ='Default Network Metrics'!H6 -> 0 | H4: ='Default Network Metrics'!I6 -> 0 | ... O4: ='Default Network Metrics'!P6 -> 0 | P4: =MIN('Event Register'!H63,'Event Register'!H44) -> 0.9 | Q4: ='Default Network Metrics'!R6 -> 0 | R4: ='Default Network Metrics'!S6 -> 0 | S4: ='Default Network Metrics'!T6 -> 0 | T4: ='Default Network Metrics'!U6 -> 0 | U4: ='Default Network Metrics'!V6 -> 0 | V4: ='Default Network Metrics'!W6 -> 0 | W4: ='Default Network Metrics'!X6 -> 0 | X4: =MAX('Event Register'!H47) -> 0
A5: ='Default Network Metrics'!B7 -> 0 | B5: ='Default Network Metrics'!C7 -> 0 | C5: ='Default Network Metrics'!D7 -> 0 | D5: ='Default Network Metrics'!E7 -> 0 | E5: ='Default Network Metrics'!F7 -> 0 | F5: ='Default Network Metrics'!G7 -> 0.9 | G5: ='Default Network Metrics'!H7 -> 0 | H5: ='Default Network Metrics'!I7 -> 0 | ... X5: ='Default Network Metrics'!Y7 -> 0
A6: ='Default Network Metrics'!B8 -> 0 | B6: ='Default Network Metrics'!C8 -> 0 | C6: ='Default Network Metrics'!D8 -> 0 | D6: ='Default Network Metrics'!E8 -> 0 | E6: ='Default Network Metrics'!F8 -> 0 | F6: ='Default Network Metrics'!G8 -> 0 | G6: ='Default Network Metrics'!H8 -> 0.9 | H6: ='Default Network Metrics'!I8 -> 0 | ... X6: ='Default Network Metrics'!Y8 -> 0
A7: ='Default Network Metrics'!B9 -> 0 | B7: ='Default Network Metrics'!C9 -> 0 | C7: ='Default Network Metrics'!D9 -> 0 | D7: ='Default Network Metrics'!E9 -> 0 | E7: ='Default Network Metrics'!F9 -> 0 | F7: ='Default Network Metrics'!G9 -> 0 | G7: ='Default Network Metrics'!H9 -> 0 | H7: ='Default Network Metrics'!I9 -> 0.9 | ... X7: ='Default Network Metrics'!Y9 -> 0.5
A8: ='Default Network Metrics'!B10 -> 0 | B8: ='Default Network Metrics'!C10 -> 0 | C8: ='Default Network Metrics'!D10 -> 0 | D8: ='Default Network Metrics'!E10 -> 0 | E8: ='Default Network Metrics'!F10 -> 0 | F8: ='Default Network Metrics'!G10 -> 0 | G8: ='Default Network Metrics'!H10 -> 0 | H8: ='Default Network Metrics'!I10 -> 0 | ... X8: ='Default Network Metrics'!Y10 -> 0.9
A9: ='Default Network Metrics'!B11 -> 0 | B9: ='Default Network Metrics'!C11 -> 0 | C9: ='Default Network Metrics'!D11 -> 0 | D9: ='Default Network Metrics'!E11 -> 0 | E9: ='Default Network Metrics'!F11 -> 0 | F9: ='Default Network Metrics'!G11 -> 0 | G9: ='Default Network Metrics'!H11 -> 0 | H9: ='Default Network Metrics'!I11 -> 0 | I9: ='Default Network Metrics'!J11 -> 0 | J9: ='Event Register'!H10 -> 0.9 | K9: ='Default Network Metrics'!L11 -> 0 | L9: ='Default Network Metrics'!M11 -> 0 | M9: ='Default Network Metrics'!N11 -> 0 | N9: ='Default Network Metrics'!O11 -> 0 | O9: ='Default Network Metrics'!P11 -> 0 | P9: ='Default Network Metrics'!Q11 -> 0 | Q9: ='Event Register'!H19 -> 1 | R9: ='Default Network Metrics'!S11 -> 0 | S9: ='Default Network Metrics'!T11 -> 0 | T9: ='Default Network Metrics'!U11 -> 0 | U9: ='Default Network Metrics'!V11 -> 0 | V9: ='Default Network Metrics'!W11 -> 0 | W9: ='Default Network Metrics'!X11 -> 0 | X9: ='Default Network Metrics'!Y11 -> 0
A10: ='Default Network Metrics'!B12 -> 0 | B10: ='Default Network Metrics'!C12 -> 0 | C10: ='Default Network Metrics'!D12 -> 0 | D10: ='Default Network Metrics'!E12 -> 0 | E10: ='Default Network Metrics'!F12 -> 0 | F10: ='Default Network Metrics'!G12 -> 0 | G10: ='Default Network Metrics'!H12 -> 0 | H10: ='Default Network Metrics'!I12 -> 0 | ... J10: ='Default Network Metrics'!K12 -> 0 | K10: ='Event Register'!H13 -> 0.9 | L10: ='Default Network Metrics'!M12 -> 0 | M10: ='Default Network Metrics'!N12 -> 0 | N10: ='Default Network Metrics'!O12 -> 0 | O10: ='Default Network Metrics'!P12 -> 0 | P10: ='Default Network Metrics'!Q12 -> 0 | Q10: ='Default Network Metrics'!R12 -> 0 | R10: ='Default Network Metrics'!S12 -> 0 | S10: ='Default Network Metrics'!T12 -> 0 | ... X10: ='Default Network Metrics'!Y12 -> 0
A11: ='Default Network Metrics'!B13 -> 0 | B11: ='Default Network Metrics'!C13 -> 0 | C11: ='Default Network Metrics'!D13 -> 0 | D11: ='Default Network Metrics'!E13 -> 0 | E11: ='Default Network Metrics'!F13 -> 0 | F11: ='Default Network Metrics'!G13 -> 0 | G11: ='Default Network Metrics'!H13 -> 0 | H11: ='Default Network Metrics'!I13 -> 0 | ... K11: ='Default Network Metrics'!L13 -> 0 | L11: ='Event Register'!H16 -> 0.9 | M11: ='Default Network Metrics'!N13 -> 0 | N11: ='Default Network Metrics'!O13 -> 0 | O11: ='Default Network Metrics'!P13 -> 0 | P11: ='Default Network Metrics'!Q13 -> 0 | Q11: ='Default Network Metrics'!R13 -> 0 | R11: ='Default Network Metrics'!S13 -> 0 | S11: ='Default Network Metrics'!T13 -> 0 | T11: ='Default Network Metrics'!U13 -> 0 | ... W11: ='Default Network Metrics'!X13 -> 0 | X11: ='Event Register'!H22 -> 0.5
A12: ='Default Network Metrics'!B14 -> 0 | B12: ='Default Network Metrics'!C14 -> 0 | C12: ='Default Network Metrics'!D14 -> 0 | D12: ='Default Network Metrics'!E14 -> 0 | E12: ='Default Network Metrics'!F14 -> 0 | F12: ='Default Network Metrics'!G14 -> 0 | G12: ='Default Network Metrics'!H14 -> 0 | H12: ='Default Network Metrics'!I14 -> 0 | ... W12: ='Default Network Metrics'!X14 -> 0 | X12: ='Event Register'!H25 -> 0.9
A13: ='Default Network Metrics'!B15 -> 0 | B13: ='Default Network Metrics'!C15 -> 0 | C13: ='Default Network Metrics'!D15 -> 0 | D13: ='Default Network Metrics'!E15 -> 0 | E13: ='Default Network Metrics'!F15 -> 0 | F13: ='Default Network Metrics'!G15 -> 0 | G13: ='Default Network Metrics'!H15 -> 0 | H13: ='Default Network Metrics'!I15 -> 0 | ... X13: ='Default Network Metrics'!Y15 -> 0
A14: ='Default Network Metrics'!B16 -> 0 | B14: ='Default Network Metrics'!C16 -> 0 | C14: =MAX('Event Register'!H57,'Event Register'!H73) -> 5 | D14: ='Default Network Metrics'!E16 -> 0 | E14: ='Default Network Metrics'!F16 -> 0 | F14: ='Default Network Metrics'!G16 -> 0 | G14: ='Default Network Metrics'!H16 -> 0 | H14: ='Default Network Metrics'!I16 -> 0 | I14: ='Default Network Metrics'!J16 -> 0 | J14: ='Default Network Metrics'!K16 -> 0 | K14: ='Default Network Metrics'!L16 -> 0 | ... N14: ='Default Network Metrics'!O16 -> 0 | O14: =MAX('Event Register'!H38,'Event Register'!H51) -> 0 | P14: ='Default Network Metrics'!Q16 -> 0 | Q14: ='Default Network Metrics'!R16 -> 0 | R14: ='Default Network Metrics'!S16 -> 0 | S14: ='Default Network Metrics'!T16 -> 0 | T14: ='Default Network Metrics'!U16 -> 0 | U14: ='Default Network Metrics'!V16 -> 0 | V14: ='Default Network Metrics'!W16 -> 0 | W14: ='Default Network Metrics'!X16 -> 0 | X14: ='Default Network Metrics'!Y16 -> 0
A15: ='Default Network Metrics'!B17 -> 0 | B15: ='Default Network Metrics'!C17 -> 0 | C15: =MAX('Event Register'!H60) -> 0 | D15: ='Default Network Metrics'!E17 -> 0 | E15: ='Default Network Metrics'!F17 -> 0 | F15: ='Default Network Metrics'!G17 -> 0 | G15: ='Default Network Metrics'!H17 -> 0 | H15: ='Default Network Metrics'!I17 -> 0 | I15: ='Default Network Metrics'!J17 -> 0 | J15: ='Default Network Metrics'!K17 -> 0 | K15: ='Default Network Metrics'!L17 -> 0 | ... O15: ='Default Network Metrics'!P17 -> 0 | P15: =MAX('Event Register'!H41,'Event Register'!H54) -> 0 | Q15: ='Default Network Metrics'!R17 -> 0 | R15: ='Default Network Metrics'!S17 -> 0 | S15: ='Default Network Metrics'!T17 -> 0 | T15: ='Default Network Metrics'!U17 -> 0 | U15: ='Default Network Metrics'!V17 -> 0 | V15: ='Default Network Metrics'!W17 -> 0 | W15: ='Default Network Metrics'!X17 -> 0 | X15: ='Default Network Metrics'!Y17 -> 0
A16: ='Default Network Metrics'!B18 -> 0.8 | B16: ='Default Network Metrics'!C18 -> 0 | C16: ='Default Network Metrics'!D18 -> 0 | D16: ='Default Network Metrics'!E18 -> 0 | E16: ='Default Network Metrics'!F18 -> 0.8 | F16: ='Default Network Metrics'!G18 -> 0 | G16: ='Default Network Metrics'!H18 -> 0 | H16: ='Default Network Metrics'!I18 -> 0 | I16: ='Event Register'!H28 -> 0.8 | J16: ='Default Network Metrics'!K18 -> 0 | K16: ='Default Network Metrics'!L18 -> 0 | L16: ='Default Network Metrics'!M18 -> 0 | M16: ='Default Network Metrics'!N18 -> 0.9 | N16: ='Default Network Metrics'!O18 -> 0 | O16: ='Default Network Metrics'!P18 -> 0 | P16: ='Default Network Metrics'!Q18 -> 0 | Q16: ='Default Network Metrics'!R18 -> 0 | ... X16: ='Default Network Metrics'!Y18 -> 0.9
A17: ='Default Network Metrics'!B19 -> 0 | B17: ='Default Network Metrics'!C19 -> 0 | C17: ='Default Network Metrics'!D19 -> 0 | D17: ='Default Network Metrics'!E19 -> 0 | E17: ='Default Network Metrics'!F19 -> 0 | F17: ='Default Network Metrics'!G19 -> 0 | G17: ='Default Network Metrics'!H19 -> 0 | H17: ='Default Network Metrics'!I19 -> 0 | ... X17: ='Default Network Metrics'!Y19 -> 0
A18: ='Default Network Metrics'!B20 -> 0.5 | B18: ='Default Network Metrics'!C20 -> 0 | C18: ='Default Network Metrics'!D20 -> 0 | D18: ='Default Network Metrics'!E20 -> 0 | E18: ='Default Network Metrics'!F20 -> 0.5 | F18: ='Default Network Metrics'!G20 -> 0 | G18: ='Default Network Metrics'!H20 -> 0 | H18: ='Default Network Metrics'!I20 -> 0 | I18: ='Event Register'!H31 -> 0.5 | J18: ='Default Network Metrics'!K20 -> 0 | K18: ='Default Network Metrics'!L20 -> 0 | L18: ='Default Network Metrics'!M20 -> 0 | M18: ='Default Network Metrics'!N20 -> 0 | N18: ='Default Network Metrics'!O20 -> 0 | O18: ='Default Network Metrics'!P20 -> 0 | P18: ='Default Network Metrics'!Q20 -> 0 | Q18: ='Default Network Metrics'!R20 -> 0 | ... X18: ='Default Network Metrics'!Y20 -> 0
A19: ='Default Network Metrics'!B21 -> 0.2 | B19: ='Default Network Metrics'!C21 -> 0 | C19: ='Default Network Metrics'!D21 -> 0 | D19: ='Default Network Metrics'!E21 -> 0 | E19: ='Default Network Metrics'!F21 -> 0.2 | F19: ='Default Network Metrics'!G21 -> 0 | G19: ='Default Network Metrics'!H21 -> 0 | H19: ='Default Network Metrics'!I21 -> 0 | I19: ='Event Register'!H34 -> 0.2 | J19: ='Default Network Metrics'!K21 -> 0 | K19: ='Default Network Metrics'!L21 -> 0 | L19: ='Default Network Metrics'!M21 -> 0 | M19: ='Default Network Metrics'!N21 -> 0 | N19: ='Default Network Metrics'!O21 -> 0 | O19: ='Default Network Metrics'!P21 -> 0 | P19: ='Default Network Metrics'!Q21 -> 0 | Q19: ='Default Network Metrics'!R21 -> 0 | ... X19: ='Default Network Metrics'!Y21 -> 0
A20: ='Default Network Metrics'!B22 -> 0 | B20: ='Default Network Metrics'!C22 -> 0 | C20: ='Default Network Metrics'!D22 -> 0 | D20: ='Default Network Metrics'!E22 -> 0 | E20: ='Default Network Metrics'!F22 -> 0 | F20: ='Default Network Metrics'!G22 -> 0 | G20: ='Default Network Metrics'!H22 -> 0 | H20: ='Default Network Metrics'!I22 -> 0 | ... X20: ='Default Network Metrics'!Y22 -> 0
A21: ='Default Network Metrics'!B23 -> 0 | B21: ='Default Network Metrics'!C23 -> 0 | C21: ='Default Network Metrics'!D23 -> 0 | D21: ='Default Network Metrics'!E23 -> 0 | E21: ='Default Network Metrics'!F23 -> 0 | F21: ='Default Network Metrics'!G23 -> 0 | G21: ='Default Network Metrics'!H23 -> 0 | H21: ='Default Network Metrics'!I23 -> 0 | ... X21: ='Default Network Metrics'!Y23 -> 0
A22: ='Default Network Metrics'!B24 -> 0 | B22: ='Default Network Metrics'!C24 -> 0 | C22: ='Default Network Metrics'!D24 -> 0 | D22: ='Default Network Metrics'!E24 -> 0 | E22: ='Default Network Metrics'!F24 -> 0 | F22: ='Default Network Metrics'!G24 -> 0 | G22: ='Default Network Metrics'!H24 -> 0 | H22: ='Default Network Metrics'!I24 -> 0 | ... X22: ='Default Network Metrics'!Y24 -> 0
A23: ='Default Network Metrics'!B25 -> 0 | B23: ='Default Network Metrics'!C25 -> 0 | C23: ='Default Network Metrics'!D25 -> 0 | D23: ='Default Network Metrics'!E25 -> 0 | E23: ='Default Network Metrics'!F25 -> 0 | F23: ='Default Network Metrics'!G25 -> 0 | G23: ='Default Network Metrics'!H25 -> 0 | H23: ='Default Network Metrics'!I25 -> 0 | ... X23: ='Default Network Metrics'!Y25 -> 0
A24: ='Default Network Metrics'!B26 -> 0 | B24: ='Default Network Metrics'!C26 -> 0 | C24: ='Default Network Metrics'!D26 -> 0 | D24: ='Default Network Metrics'!E26 -> 0 | E24: ='Default Network Metrics'!F26 -> 0 | F24: ='Default Network Metrics'!G26 -> 0 | G24: ='Default Network Metrics'!H26 -> 0 | H24: ='Default Network Metrics'!I26 -> 0 | ... X24: ='Default Network Metrics'!Y26 -> 0

Sheet COD
A1: ='Default Network Metrics'!B31 -> 0 | B1: ='Default Network Metrics'!C31 -> 100 | C1: ='Default Network Metrics'!D31 -> 0 | D1: ='Default Network Metrics'!E31 -> 0 | E1: ='Default Network Metrics'!F31 -> 0 | F1: ='Default Network Metrics'!G31 -> 0 | G1: ='Default Network Metrics'!H31 -> 0 | H1: ='Default Network Metrics'!I31 -> 0 | ... X1: ='Default Network Metrics'!Y31 -> 0
A2: ='Default Network Metrics'!B32 -> 0 | B2: ='Default Network Metrics'!C32 -> 0 | C2: ='Default Network Metrics'!D32 -> 100 | D2: ='Default Network Metrics'!E32 -> 0 | E2: ='Default Network Metrics'!F32 -> 0 | F2: ='Default Network Metrics'!G32 -> 0 | G2: ='Default Network Metrics'!H32 -> 0 | H2: ='Default Network Metrics'!I32 -> 0 | ... X2: ='Default Network Metrics'!Y32 -> 0
A3: ='Default Network Metrics'!B33 -> 0 | B3: ='Default Network Metrics'!C33 -> 0 | C3: ='Default Network Metrics'!D33 -> 0 | D3: ='Default Network Metrics'!E33 -> 100 | E3: ='Default Network Metrics'!F33 -> 0 | F3: ='Default Network Metrics'!G33 -> 0 | G3: ='Default Network Metrics'!H33 -> 0 | H3: ='Default Network Metrics'!I33 -> 0 | ... X3: ='Default Network Metrics'!Y33 -> 50
A4: ='Default Network Metrics'!B34 -> 0 | B4: ='Default Network Metrics'!C34 -> 0 | C4: ='Default Network Metrics'!D34 -> 0 | D4: ='Default Network Metrics'!E34 -> 0 | E4: ='Default Network Metrics'!F34 -> 0 | F4: ='Default Network Metrics'!G34 -> 0 | G4: ='Default Network Metrics'!H34 -> 0 | H4: ='Default Network Metrics'!I34 -> 0 | ... O4: ='Default Network Metrics'!P34 -> 0 | P4: =MIN('Event Register'!H64,'Event Register'!H45) -> 100 | Q4: ='Default Network Metrics'!R34 -> 0 | R4: ='Default Network Metrics'!S34 -> 0 | S4: ='Default Network Metrics'!T34 -> 0 | T4: ='Default Network Metrics'!U34 -> 0 | U4: ='Default Network Metrics'!V34 -> 0 | V4: ='Default Network Metrics'!W34 -> 0 | W4: ='Default Network Metrics'!X34 -> 0 | X4: =MAX('Event Register'!H48) -> 0
A5: ='Default Network Metrics'!B35 -> 0 | B5: ='Default Network Metrics'!C35 -> 0 | C5: ='Default Network Metrics'!D35 -> 0 | D5: ='Default Network Metrics'!E35 -> 0 | E5: ='Default Network Metrics'!F35 -> 0 | F5: ='Default Network Metrics'!G35 -> 100 | G5: ='Default Network Metrics'!H35 -> 0 | H5: ='Default Network Metrics'!I35 -> 0 | ... X5: ='Default Network Metrics'!Y35 -> 0
A6: ='Default Network Metrics'!B36 -> 0 | B6: ='Default Network Metrics'!C36 -> 0 | C6: ='Default Network Metrics'!D36 -> 0 | D6: ='Default Network Metrics'!E36 -> 0 | E6: ='Default Network Metrics'!F36 -> 0 | F6: ='Default Network Metrics'!G36 -> 0 | G6: ='Default Network Metrics'!H36 -> 100 | H6: ='Default Network Metrics'!I36 -> 0 | ... X6: ='Default Network Metrics'!Y36 -> 0
A7: ='Default Network Metrics'!B37 -> 0 | B7: ='Default Network Metrics'!C37 -> 0 | C7: ='Default Network Metrics'!D37 -> 0 | D7: ='Default Network Metrics'!E37 -> 0 | E7: ='Default Network Metrics'!F37 -> 0 | F7: ='Default Network Metrics'!G37 -> 0 | G7: ='Default Network Metrics'!H37 -> 0 | H7: ='Default Network Metrics'!I37 -> 100 | ... X7: ='Default Network Metrics'!Y37 -> 50
A8: ='Default Network Metrics'!B38 -> 0 | B8: ='Default Network Metrics'!C38 -> 0 | C8: ='Default Network Metrics'!D38 -> 0 | D8: ='Default Network Metrics'!E38 -> 0 | E8: ='Default Network Metrics'!F38 -> 0 | F8: ='Default Network Metrics'!G38 -> 0 | G8: ='Default Network Metrics'!H38 -> 0 | H8: ='Default Network Metrics'!I38 -> 0 | ... X8: ='Default Network Metrics'!Y38 -> 100
A9: ='Default Network Metrics'!B39 -> 0 | B9: ='Default Network Metrics'!C39 -> 0 | C9: ='Default Network Metrics'!D39 -> 0 | D9: ='Default Network Metrics'!E39 -> 0 | E9: ='Default Network Metrics'!F39 -> 0 | F9: ='Default Network Metrics'!G39 -> 0 | G9: ='Default Network Metrics'!H39 -> 0 | H9: ='Default Network Metrics'!I39 -> 0 | I9: ='Default Network Metrics'!J39 -> 0 | J9: ='Event Register'!H11 -> 100 | K9: ='Default Network Metrics'!L39 -> 0 | L9: ='Default Network Metrics'!M39 -> 0 | M9: ='Default Network Metrics'!N39 -> 0 | N9: ='Default Network Metrics'!O39 -> 0 | O9: ='Default Network Metrics'!P39 -> 0 | P9: ='Default Network Metrics'!Q39 -> 0 | Q9: ='Event Register'!H20 -> 100 | R9: ='Default Network Metrics'!S39 -> 0 | S9: ='Default Network Metrics'!T39 -> 0 | T9: ='Default Network Metrics'!U39 -> 0 | U9: ='Default Network Metrics'!V39 -> 0 | V9: ='Default Network Metrics'!W39 -> 0 | W9: ='Default Network Metrics'!X39 -> 0 | X9: ='Default Network Metrics'!Y39 -> 0
A10: ='Default Network Metrics'!B40 -> 0 | B10: ='Default Network Metrics'!C40 -> 0 | C10: ='Default Network Metrics'!D40 -> 0 | D10: ='Default Network Metrics'!E40 -> 0 | E10: ='Default Network Metrics'!F40 -> 0 | F10: ='Default Network Metrics'!G40 -> 0 | G10: ='Default Network Metrics'!H40 -> 0 | H10: ='Default Network Metrics'!I40 -> 0 | ... J10: ='Default Network Metrics'!K40 -> 0 | K10: ='Event Register'!H14 -> 100 | L10: ='Default Network Metrics'!M40 -> 0 | M10: ='Default Network Metrics'!N40 -> 0 | N10: ='Default Network Metrics'!O40 -> 0 | O10: ='Default Network Metrics'!P40 -> 0 | P10: ='Default Network Metrics'!Q40 -> 0 | Q10: ='Default Network Metrics'!R40 -> 0 | R10: ='Default Network Metrics'!S40 -> 0 | S10: ='Default Network Metrics'!T40 -> 0 | ... X10: ='Default Network Metrics'!Y40 -> 0
A11: ='Default Network Metrics'!B41 -> 0 | B11: ='Default Network Metrics'!C41 -> 0 | C11: ='Default Network Metrics'!D41 -> 0 | D11: ='Default Network Metrics'!E41 -> 0 | E11: ='Default Network Metrics'!F41 -> 0 | F11: ='Default Network Metrics'!G41 -> 0 | G11: ='Default Network Metrics'!H41 -> 0 | H11: ='Default Network Metrics'!I41 -> 0 | ... K11: ='Default Network Metrics'!L41 -> 0 | L11: ='Event Register'!H17 -> 100 | M11: ='Default Network Metrics'!N41 -> 0 | N11: ='Default Network Metrics'!O41 -> 0 | O11: ='Default Network Metrics'!P41 -> 0 | P11: ='Default Network Metrics'!Q41 -> 0 | Q11: ='Default Network Metrics'!R41 -> 0 | R11: ='Default Network Metrics'!S41 -> 0 | S11: ='Default Network Metrics'!T41 -> 0 | T11: ='Default Network Metrics'!U41 -> 0 | ... W11: ='Default Network Metrics'!X41 -> 0 | X11: ='Event Register'!H23 -> 50
A12: ='Default Network Metrics'!B42 -> 0 | B12: ='Default Network Metrics'!C42 -> 0 | C12: ='Default Network Metrics'!D42 -> 0 | D12: ='Default Network Metrics'!E42 -> 0 | E12: ='Default Network Metrics'!F42 -> 0 | F12: ='Default Network Metrics'!G42 -> 0 | G12: ='Default Network Metrics'!H42 -> 0 | H12: ='Default Network Metrics'!I42 -> 0 | ... W12: ='Default Network Metrics'!X42 -> 0 | X12: ='Event Register'!H26 -> 100
A13: ='Default Network Metrics'!B43 -> 0 | B13: ='Default Network Metrics'!C43 -> 0 | C13: ='Default Network Metrics'!D43 -> 0 | D13: ='Default Network Metrics'!E43 -> 0 | E13: ='Default Network Metrics'!F43 -> 0 | F13: ='Default Network Metrics'!G43 -> 0 | G13: ='Default Network Metrics'!H43 -> 0 | H13: ='Default Network Metrics'!I43 -> 0 | ... X13: ='Default Network Metrics'!Y43 -> 0
A14: ='Default Network Metrics'!B44 -> 0 | B14: ='Default Network Metrics'!C44 -> 0 | C14: ='Default Network Metrics'!D44 -> 50 | D14: ='Default Network Metrics'!E44 -> 0 | E14: ='Default Network Metrics'!F44 -> 0 | F14: ='Default Network Metrics'!G44 -> 0 | G14: ='Default Network Metrics'!H44 -> 0 | H14: ='Default Network Metrics'!I44 -> 0 | ... N14: ='Default Network Metrics'!O44 -> 0 | O14: =MAX('Event Register'!H39,'Event Register'!H52) -> 0 | P14: ='Default Network Metrics'!Q44 -> 0 | Q14: ='Default Network Metrics'!R44 -> 0 | R14: ='Default Network Metrics'!S44 -> 0 | S14: ='Default Network Metrics'!T44 -> 0 | T14: ='Default Network Metrics'!U44 -> 0 | U14: ='Default Network Metrics'!V44 -> 0 | V14: ='Default Network Metrics'!W44 -> 0 | W14: ='Default Network Metrics'!X44 -> 0 | X14: ='Default Network Metrics'!Y44 -> 0
A15: ='Default Network Metrics'!B45 -> 0 | B15: ='Default Network Metrics'!C45 -> 0 | C15: ='Default Network Metrics'!D45 -> 0 | D15: ='Default Network Metrics'!E45 -> 0 | E15: ='Default Network Metrics'!F45 -> 0 | F15: ='Default Network Metrics'!G45 -> 0 | G15: ='Default Network Metrics'!H45 -> 0 | H15: ='Default Network Metrics'!I45 -> 0 | ... O15: ='Default Network Metrics'!P45 -> 0 | P15: =MAX('Event Register'!H42,'Event Register'!H55) -> 0 | Q15: ='Default Network Metrics'!R45 -> 0 | R15: ='Default Network Metrics'!S45 -> 0 | S15: ='Default Network Metrics'!T45 -> 0 | T15: ='Default Network Metrics'!U45 -> 0 | U15: ='Default Network Metrics'!V45 -> 0 | V15: ='Default Network Metrics'!W45 -> 0 | W15: ='Default Network Metrics'!X45 -> 0 | X15: ='Default Network Metrics'!Y45 -> 0
A16: ='Default Network Metrics'!B46 -> 90 | B16: ='Default Network Metrics'!C46 -> 0 | C16: ='Default Network Metrics'!D46 -> 0 | D16: ='Default Network Metrics'!E46 -> 0 | E16: ='Default Network Metrics'!F46 -> 90 | F16: ='Default Network Metrics'!G46 -> 0 | G16: ='Default Network Metrics'!H46 -> 0 | H16: ='Default Network Metrics'!I46 -> 0 | I16: ='Event Register'!H29 -> 90 | J16: ='Default Network Metrics'!K46 -> 0 | K16: ='Default Network Metrics'!L46 -> 0 | L16: ='Default Network Metrics'!M46 -> 0 | M16: ='Default Network Metrics'!N46 -> 100 | N16: ='Default Network Metrics'!O46 -> 0 | O16: ='Default Network Metrics'!P46 -> 0 | P16: ='Default Network Metrics'!Q46 -> 0 | Q16: ='Default Network Metrics'!R46 -> 0 | ... X16: ='Default Network Metrics'!Y46 -> 100
A17: ='Default Network Metrics'!B47 -> 0 | B17: ='Default Network Metrics'!C47 -> 0 | C17: ='Default Network Metrics'!D47 -> 0 | D17: ='Default Network Metrics'!E47 -> 0 | E17: ='Default Network Metrics'!F47 -> 0 | F17: ='Default Network Metrics'!G47 -> 0 | G17: ='Default Network Metrics'!H47 -> 0 | H17: ='Default Network Metrics'!I47 -> 0 | ... X17: ='Default Network Metrics'!Y47 -> 0
A18: ='Default Network Metrics'!B48 -> 80 | B18: ='Default Network Metrics'!C48 -> 0 | C18: ='Default Network Metrics'!D48 -> 0 | D18: ='Default Network Metrics'!E48 -> 0 | E18: ='Default Network Metrics'!F48 -> 80 | F18: ='Default Network Metrics'!G48 -> 0 | G18: ='Default Network Metrics'!H48 -> 0 | H18: ='Default Network Metrics'!I48 -> 0 | I18: ='Event Register'!H32 -> 80 | J18: ='Default Network Metrics'!K48 -> 0 | K18: ='Default Network Metrics'!L48 -> 0 | L18: ='Default Network Metrics'!M48 -> 0 | M18: ='Default Network Metrics'!N48 -> 0 | N18: ='Default Network Metrics'!O48 -> 0 | O18: ='Default Network Metrics'!P48 -> 0 | P18: ='Default Network Metrics'!Q48 -> 0 | Q18: ='Default Network Metrics'!R48 -> 0 | ... X18: ='Default Network Metrics'!Y48 -> 0
A19: ='Default Network Metrics'!B49 -> 50 | B19: ='Default Network Metrics'!C49 -> 0 | C19: ='Default Network Metrics'!D49 -> 0 | D19: ='Default Network Metrics'!E49 -> 0 | E19: ='Default Network Metrics'!F49 -> 50 | F19: ='Default Network Metrics'!G49 -> 0 | G19: ='Default Network Metrics'!H49 -> 0 | H19: ='Default Network Metrics'!I49 -> 0 | I19: ='Event Register'!H35 -> 50 | J19: ='Default Network Metrics'!K49 -> 0 | K19: ='Default Network Metrics'!L49 -> 0 | L19: ='Default Network Metrics'!M49 -> 0 | M19: ='Default Network Metrics'!N49 -> 0 | N19: ='Default Network Metrics'!O49 -> 0 | O19: ='Default Network Metrics'!P49 -> 0 | P19: ='Default Network Metrics'!Q49 -> 0 | Q19: ='Default Network Metrics'!R49 -> 0 | ... X19: ='Default Network Metrics'!Y49 -> 0
A20: ='Default Network Metrics'!B50 -> 0 | B20: ='Default Network Metrics'!C50 -> 0 | C20: ='Default Network Metrics'!D50 -> 0 | D20: ='Default Network Metrics'!E50 -> 0 | E20: ='Default Network Metrics'!F50 -> 0 | F20: ='Default Network Metrics'!G50 -> 0 | G20: ='Default Network Metrics'!H50 -> 0 | H20: ='Default Network Metrics'!I50 -> 0 | ... X20: ='Default Network Metrics'!Y50 -> 0
A21: ='Default Network Metrics'!B51 -> 0 | B21: ='Default Network Metrics'!C51 -> 0 | C21: ='Default Network Metrics'!D51 -> 0 | D21: ='Default Network Metrics'!E51 -> 0 | E21: ='Default Network Metrics'!F51 -> 0 | F21: ='Default Network Metrics'!G51 -> 0 | G21: ='Default Network Metrics'!H51 -> 0 | H21: ='Default Network Metrics'!I51 -> 0 | ... X21: ='Default Network Metrics'!Y51 -> 0
A22: ='Default Network Metrics'!B52 -> 0 | B22: ='Default Network Metrics'!C52 -> 0 | C22: ='Default Network Metrics'!D52 -> 0 | D22: ='Default Network Metrics'!E52 -> 0 | E22: ='Default Network Metrics'!F52 -> 0 | F22: ='Default Network Metrics'!G52 -> 0 | G22: ='Default Network Metrics'!H52 -> 0 | H22: ='Default Network Metrics'!I52 -> 0 | ... X22: ='Default Network Metrics'!Y52 -> 0
A23: ='Default Network Metrics'!B53 -> 0 | B23: ='Default Network Metrics'!C53 -> 0 | C23: ='Default Network Metrics'!D53 -> 0 | D23: ='Default Network Metrics'!E53 -> 0 | E23: ='Default Network Metrics'!F53 -> 0 | F23: ='Default Network Metrics'!G53 -> 0 | G23: ='Default Network Metrics'!H53 -> 0 | H23: ='Default Network Metrics'!I53 -> 0 | ... X23: ='Default Network Metrics'!Y53 -> 0
A24: ='Default Network Metrics'!B54 -> 0 | B24: ='Default Network Metrics'!C54 -> 0 | C24: ='Default Network Metrics'!D54 -> 0 | D24: ='Default Network Metrics'!E54 -> 0 | E24: ='Default Network Metrics'!F54 -> 0 | F24: ='Default Network Metrics'!G54 -> 0 | G24: ='Default Network Metrics'!H54 -> 0 | H24: ='Default Network Metrics'!I54 -> 0 | ... X24: ='Default Network Metrics'!Y54 -> 0

Sheet IOD
A1: ='Default Network Metrics'!B59 -> 0 | B1: ='Default Network Metrics'!C59 -> 90 | C1: ='Default Network Metrics'!D59 -> 0 | D1: ='Default Network Metrics'!E59 -> 0 | E1: ='Default Network Metrics'!F59 -> 0 | F1: ='Default Network Metrics'!G59 -> 0 | G1: ='Default Network Metrics'!H59 -> 0 | H1: ='Default Network Metrics'!I59 -> 0 | ... X1: ='Default Network Metrics'!Y59 -> 0
A2: ='Default Network Metrics'!B60 -> 0 | B2: ='Default Network Metrics'!C60 -> 0 | C2: ='Default Network Metrics'!D60 -> 90 | D2: ='Default Network Metrics'!E60 -> 0 | E2: ='Default Network Metrics'!F60 -> 0 | F2: ='Default Network Metrics'!G60 -> 0 | G2: ='Default Network Metrics'!H60 -> 0 | H2: ='Default Network Metrics'!I60 -> 0 | ... X2: ='Default Network Metrics'!Y60 -> 0
A3: ='Default Network Metrics'!B61 -> 0 | B3: ='Default Network Metrics'!C61 -> 0 | C3: ='Default Network Metrics'!D61 -> 0 | D3: ='Default Network Metrics'!E61 -> 90 | E3: ='Default Network Metrics'!F61 -> 0 | F3: ='Default Network Metrics'!G61 -> 0 | G3: ='Default Network Metrics'!H61 -> 0 | H3: ='Default Network Metrics'!I61 -> 0 | ... X3: ='Default Network Metrics'!Y61 -> 50
A4: ='Default Network Metrics'!B62 -> 0 | B4: ='Default Network Metrics'!C62 -> 0 | C4: ='Default Network Metrics'!D62 -> 0 | D4: ='Default Network Metrics'!E62 -> 0 | E4: ='Default Network Metrics'!F62 -> 0 | F4: ='Default Network Metrics'!G62 -> 0 | G4: ='Default Network Metrics'!H62 -> 0 | H4: ='Default Network Metrics'!I62 -> 0 | ... O4: ='Default Network Metrics'!P62 -> 0 | P4: =MIN('Event Register'!H65,'Event Register'!H46) -> 80 | Q4: ='Default Network Metrics'!R62 -> 0 | R4: ='Default Network Metrics'!S62 -> 0 | S4: ='Default Network Metrics'!T62 -> 0 | T4: ='Default Network Metrics'!U62 -> 0 | U4: ='Default Network Metrics'!V62 -> 0 | V4: ='Default Network Metrics'!W62 -> 0 | W4: ='Default Network Metrics'!X62 -> 0 | X4: =MAX('Event Register'!H49) -> 0
A5: ='Default Network Metrics'!B63 -> 0 | B5: ='Default Network Metrics'!C63 -> 0 | C5: ='Default Network Metrics'!D63 -> 0 | D5: ='Default Network Metrics'!E63 -> 0 | E5: ='Default Network Metrics'!F63 -> 0 | F5: ='Default Network Metrics'!G63 -> 90 | G5: ='Default Network Metrics'!H63 -> 0 | H5: ='Default Network Metrics'!I63 -> 0 | ... X5: ='Default Network Metrics'!Y63 -> 0
A6: ='Default Network Metrics'!B64 -> 0 | B6: ='Default Network Metrics'!C64 -> 0 | C6: ='Default Network Metrics'!D64 -> 0 | D6: ='Default Network Metrics'!E64 -> 0 | E6: ='Default Network Metrics'!F64 -> 0 | F6: ='Default Network Metrics'!G64 -> 0 | G6: ='Default Network Metrics'!H64 -> 90 | H6: ='Default Network Metrics'!I64 -> 0 | ... X6: ='Default Network Metrics'!Y64 -> 0
A7: ='Default Network Metrics'!B65 -> 0 | B7: ='Default Network Metrics'!C65 -> 0 | C7: ='Default Network Metrics'!D65 -> 0 | D7: ='Default Network Metrics'!E65 -> 0 | E7: ='Default Network Metrics'!F65 -> 0 | F7: ='Default Network Metrics'!G65 -> 0 | G7: ='Default Network Metrics'!H65 -> 0 | H7: ='Default Network Metrics'!I65 -> 90 | ... X7: ='Default Network Metrics'!Y65 -> 50
A8: ='Default Network Metrics'!B66 -> 0 | B8: ='Default Network Metrics'!C66 -> 0 | C8: ='Default Network Metrics'!D66 -> 0 | D8: ='Default Network Metrics'!E66 -> 0 | E8: ='Default Network Metrics'!F66 -> 0 | F8: ='Default Network Metrics'!G66 -> 0 | G8: ='Default Network Metrics'!H66 -> 0 | H8: ='Default Network Metrics'!I66 -> 0 | ... X8: ='Default Network Metrics'!Y66 -> 100
A9: ='Default Network Metrics'!B67 -> 0 | B9: ='Default Network Metrics'!C67 -> 0 | C9: ='Default Network Metrics'!D67 -> 0 | D9: ='Default Network Metrics'!E67 -> 0 | E9: ='Default Network Metrics'!F67 -> 0 | F9: ='Default Network Metrics'!G67 -> 0 | G9: ='Default Network Metrics'!H67 -> 0 | H9: ='Default Network Metrics'!I67 -> 0 | I9: ='Default Network Metrics'!J67 -> 0 | J9: ='Event Register'!H12 -> 90 | K9: ='Default Network Metrics'!L67 -> 0 | L9: ='Default Network Metrics'!M67 -> 0 | M9: ='Default Network Metrics'!N67 -> 0 | N9: ='Default Network Metrics'!O67 -> 0 | O9: ='Default Network Metrics'!P67 -> 0 | P9: ='Default Network Metrics'!Q67 -> 0 | Q9: ='Event Register'!H21 -> 10 | R9: ='Default Network Metrics'!S67 -> 0 | S9: ='Default Network Metrics'!T67 -> 0 | T9: ='Default Network Metrics'!U67 -> 0 | U9: ='Default Network Metrics'!V67 -> 0 | V9: ='Default Network Metrics'!W67 -> 0 | W9: ='Default Network Metrics'!X67 -> 0 | X9: ='Default Network Metrics'!Y67 -> 0
A10: ='Default Network Metrics'!B68 -> 0 | B10: ='Default Network Metrics'!C68 -> 0 | C10: ='Default Network Metrics'!D68 -> 0 | D10: ='Default Network Metrics'!E68 -> 0 | E10: ='Default Network Metrics'!F68 -> 0 | F10: ='Default Network Metrics'!G68 -> 0 | G10: ='Default Network Metrics'!H68 -> 0 | H10: ='Default Network Metrics'!I68 -> 0 | ... J10: ='Default Network Metrics'!K68 -> 0 | K10: ='Event Register'!H15 -> 90 | L10: ='Default Network Metrics'!M68 -> 0 | M10: ='Default Network Metrics'!N68 -> 0 | N10: ='Default Network Metrics'!O68 -> 0 | O10: ='Default Network Metrics'!P68 -> 0 | P10: ='Default Network Metrics'!Q68 -> 0 | Q10: ='Default Network Metrics'!R68 -> 0 | R10: ='Default Network Metrics'!S68 -> 0 | S10: ='Default Network Metrics'!T68 -> 0 | ... X10: ='Default Network Metrics'!Y68 -> 0
A11: ='Default Network Metrics'!B69 -> 0 | B11: ='Default Network Metrics'!C69 -> 0 | C11: ='Default Network Metrics'!D69 -> 0 | D11: ='Default Network Metrics'!E69 -> 0 | E11: ='Default Network Metrics'!F69 -> 0 | F11: ='Default Network Metrics'!G69 -> 0 | G11: ='Default Network Metrics'!H69 -> 0 | H11: ='Default Network Metrics'!I69 -> 0 | ... K11: ='Default Network Metrics'!L69 -> 0 | L11: ='Event Register'!H18 -> 90 | M11: ='Default Network Metrics'!N69 -> 0 | N11: ='Default Network Metrics'!O69 -> 0 | O11: ='Default Network Metrics'!P69 -> 0 | P11: ='Default Network Metrics'!Q69 -> 0 | Q11: ='Default Network Metrics'!R69 -> 0 | R11: ='Default Network Metrics'!S69 -> 0 | S11: ='Default Network Metrics'!T69 -> 0 | T11: ='Default Network Metrics'!U69 -> 0 | ... W11: ='Default Network Metrics'!X69 -> 0 | X11: ='Event Register'!H24 -> 50
A12: ='Default Network Metrics'!B70 -> 0 | B12: ='Default Network Metrics'!C70 -> 0 | C12: ='Default Network Metrics'!D70 -> 0 | D12: ='Default Network Metrics'!E70 -> 0 | E12: ='Default Network Metrics'!F70 -> 0 | F12: ='Default Network Metrics'!G70 -> 0 | G12: ='Default Network Metrics'!H70 -> 0 | H12: ='Default Network Metrics'!I70 -> 0 | ... W12: ='Default Network Metrics'!X70 -> 0 | X12: ='Event Register'!H27 -> 100
A13: ='Default Network Metrics'!B71 -> 0 | B13: ='Default Network Metrics'!C71 -> 0 | C13: ='Default Network Metrics'!D71 -> 0 | D13: ='Default Network Metrics'!E71 -> 0 | E13: ='Default Network Metrics'!F71 -> 0 | F13: ='Default Network Metrics'!G71 -> 0 | G13: ='Default Network Metrics'!H71 -> 0 | H13: ='Default Network Metrics'!I71 -> 0 | ... X13: ='Default Network Metrics'!Y71 -> 0
A14: ='Default Network Metrics'!B72 -> 0 | B14: ='Default Network Metrics'!C72 -> 0 | C14: ='Default Network Metrics'!D72 -> 70 | D14: ='Default Network Metrics'!E72 -> 0 | E14: ='Default Network Metrics'!F72 -> 0 | F14: ='Default Network Metrics'!G72 -> 0 | G14: ='Default Network Metrics'!H72 -> 0 | H14: ='Default Network Metrics'!I72 -> 0 | ... N14: ='Default Network Metrics'!O72 -> 0 | O14: =MAX('Event Register'!H40,'Event Register'!H53) -> 0 | P14: ='Default Network Metrics'!Q72 -> 0 | Q14: ='Default Network Metrics'!R72 -> 0 | R14: ='Default Network Metrics'!S72 -> 0 | S14: ='Default Network Metrics'!T72 -> 0 | T14: ='Default Network Metrics'!U72 -> 0 | U14: ='Default Network Metrics'!V72 -> 0 | V14: ='Default Network Metrics'!W72 -> 0 | W14: ='Default Network Metrics'!X72 -> 0 | X14: ='Default Network Metrics'!Y72 -> 0
A15: ='Default Network Metrics'!B73 -> 0 | B15: ='Default Network Metrics'!C73 -> 0 | C15: ='Default Network Metrics'!D73 -> 0 | D15: ='Default Network Metrics'!E73 -> 0 | E15: ='Default Network Metrics'!F73 -> 0 | F15: ='Default Network Metrics'!G73 -> 0 | G15: ='Default Network Metrics'!H73 -> 0 | H15: ='Default Network Metrics'!I73 -> 0 | ... O15: ='Default Network Metrics'!P73 -> 0 | P15: =MAX('Event Register'!H43,'Event Register'!H56) -> 0 | Q15: ='Default Network Metrics'!R73 -> 0 | R15: ='Default Network Metrics'!S73 -> 0 | S15: ='Default Network Metrics'!T73 -> 0 | T15: ='Default Network Metrics'!U73 -> 0 | U15: ='Default Network Metrics'!V73 -> 0 | V15: ='Default Network Metrics'!W73 -> 0 | W15: ='Default Network Metrics'!X73 -> 0 | X15: ='Default Network Metrics'!Y73 -> 0
A16: ='Default Network Metrics'!B74 -> 90 | B16: ='Default Network Metrics'!C74 -> 0 | C16: ='Default Network Metrics'!D74 -> 0 | D16: ='Default Network Metrics'!E74 -> 0 | E16: ='Default Network Metrics'!F74 -> 90 | F16: ='Default Network Metrics'!G74 -> 0 | G16: ='Default Network Metrics'!H74 -> 0 | H16: ='Default Network Metrics'!I74 -> 0 | I16: ='Event Register'!H30 -> 90 | J16: ='Default Network Metrics'!K74 -> 0 | K16: ='Default Network Metrics'!L74 -> 0 | L16: ='Default Network Metrics'!M74 -> 0 | M16: ='Default Network Metrics'!N74 -> 90 | N16: ='Default Network Metrics'!O74 -> 0 | O16: ='Default Network Metrics'!P74 -> 0 | P16: ='Default Network Metrics'!Q74 -> 0 | Q16: ='Default Network Metrics'!R74 -> 0 | ... X16: ='Default Network Metrics'!Y74 -> 100
A17: ='Default Network Metrics'!B75 -> 0 | B17: ='Default Network Metrics'!C75 -> 0 | C17: ='Default Network Metrics'!D75 -> 0 | D17: ='Default Network Metrics'!E75 -> 0 | E17: ='Default Network Metrics'!F75 -> 0 | F17: ='Default Network Metrics'!G75 -> 0 | G17: ='Default Network Metrics'!H75 -> 0 | H17: ='Default Network Metrics'!I75 -> 0 | ... X17: ='Default Network Metrics'!Y75 -> 0
A18: ='Default Network Metrics'!B76 -> 50 | B18: ='Default Network Metrics'!C76 -> 0 | C18: ='Default Network Metrics'!D76 -> 0 | D18: ='Default Network Metrics'!E76 -> 0 | E18: ='Default Network Metrics'!F76 -> 50 | F18: ='Default Network Metrics'!G76 -> 0 | G18: ='Default Network Metrics'!H76 -> 0 | H18: ='Default Network Metrics'!I76 -> 0 | I18: ='Event Register'!H33 -> 50 | J18: ='Default Network Metrics'!K76 -> 0 | K18: ='Default Network Metrics'!L76 -> 0 | L18: ='Default Network Metrics'!M76 -> 0 | M18: ='Default Network Metrics'!N76 -> 0 | N18: ='Default Network Metrics'!O76 -> 0 | O18: ='Default Network Metrics'!P76 -> 0 | P18: ='Default Network Metrics'!Q76 -> 0 | Q18: ='Default Network Metrics'!R76 -> 0 | ... X18: ='Default Network Metrics'!Y76 -> 0
A19: ='Default Network Metrics'!B77 -> 50 | B19: ='Default Network Metrics'!C77 -> 0 | C19: ='Default Network Metrics'!D77 -> 0 | D19: ='Default Network Metrics'!E77 -> 0 | E19: ='Default Network Metrics'!F77 -> 50 | F19: ='Default Network Metrics'!G77 -> 0 | G19: ='Default Network Metrics'!H77 -> 0 | H19: ='Default Network Metrics'!I77 -> 0 | I19: ='Event Register'!H36 -> 50 | J19: ='Default Network Metrics'!K77 -> 0 | K19: ='Default Network Metrics'!L77 -> 0 | L19: ='Default Network Metrics'!M77 -> 0 | M19: ='Default Network Metrics'!N77 -> 0 | N19: ='Default Network Metrics'!O77 -> 0 | O19: ='Default Network Metrics'!P77 -> 0 | P19: ='Default Network Metrics'!Q77 -> 0 | Q19: ='Default Network Metrics'!R77 -> 0 | ... X19: ='Default Network Metrics'!Y77 -> 0
A20: ='Default Network Metrics'!B78 -> 0 | B20: ='Default Network Metrics'!C78 -> 0 | C20: ='Default Network Metrics'!D78 -> 0 | D20: ='Default Network Metrics'!E78 -> 0 | E20: ='Default Network Metrics'!F78 -> 0 | F20: ='Default Network Metrics'!G78 -> 0 | G20: ='Default Network Metrics'!H78 -> 0 | H20: ='Default Network Metrics'!I78 -> 0 | ... X20: ='Default Network Metrics'!Y78 -> 0
A21: ='Default Network Metrics'!B79 -> 0 | B21: ='Default Network Metrics'!C79 -> 0 | C21: ='Default Network Metrics'!D79 -> 0 | D21: ='Default Network Metrics'!E79 -> 0 | E21: ='Default Network Metrics'!F79 -> 0 | F21: ='Default Network Metrics'!G79 -> 0 | G21: ='Default Network Metrics'!H79 -> 0 | H21: ='Default Network Metrics'!I79 -> 0 | ... X21: ='Default Network Metrics'!Y79 -> 0
A22: ='Default Network Metrics'!B80 -> 0 | B22: ='Default Network Metrics'!C80 -> 0 | C22: ='Default Network Metrics'!D80 -> 0 | D22: ='Default Network Metrics'!E80 -> 0 | E22: ='Default Network Metrics'!F80 -> 0 | F22: ='Default Network Metrics'!G80 -> 0 | G22: ='Default Network Metrics'!H80 -> 0 | H22: ='Default Network Metrics'!I80 -> 0 | ... X22: ='Default Network Metrics'!Y80 -> 0
A23: ='Default Network Metrics'!B81 -> 0 | B23: ='Default Network Metrics'!C81 -> 0 | C23: ='Default Network Metrics'!D81 -> 0 | D23: ='Default Network Metrics'!E81 -> 0 | E23: ='Default Network Metrics'!F81 -> 0 | F23: ='Default Network Metrics'!G81 -> 0 | G23: ='Default Network Metrics'!H81 -> 0 | H23: ='Default Network Metrics'!I81 -> 0 | ... X23: ='Default Network Metrics'!Y81 -> 0
A24: ='Default Network Metrics'!B82 -> 0 | B24: ='Default Network Metrics'!C82 -> 0 | C24: ='Default Network Metrics'!D82 -> 0 | D24: ='Default Network Metrics'!E82 -> 0 | E24: ='Default Network Metrics'!F82 -> 0 | F24: ='Default Network Metrics'!G82 -> 0 | G24: ='Default Network Metrics'!H82 -> 0 | H24: ='Default Network Metrics'!I82 -> 0 | ... X24: ='Default Network Metrics'!Y82 -> 0

Sheet SE
A1: ='Default Network Metrics'!AC3 -> B | B1: ='Default Network Metrics'!AD3 -> 5 | C1: ='Event Register'!H66 -> 5
A2: ='Default Network Metrics'!AC4 -> B | B2: ='Default Network Metrics'!AD4 -> 5 | C2: ='Default Network Metrics'!AE4 -> 2
A3: ='Default Network Metrics'!AC5 -> B | B3: ='Default Network Metrics'!AD5 -> 5 | C3: ='Default Network Metrics'!AE5 -> 2
A4: ='Default Network Metrics'!AC6 -> B | B4: ='Default Network Metrics'!AD6 -> 5 | C4: ='Default Network Metrics'!AE6 -> 2
A5: ='Default Network Metrics'!AC7 -> B | B5: ='Default Network Metrics'!AD7 -> 5 | C5: ='Event Register'!H67 -> 5
A6: ='Default Network Metrics'!AC8 -> B | B6: ='Default Network Metrics'!AD8 -> 5 | C6: ='Default Network Metrics'!AE8 -> 2
A7: ='Default Network Metrics'!AC9 -> B | B7: ='Default Network Metrics'!AD9 -> 5 | C7: ='Default Network Metrics'!AE9 -> 2
A8: ='Default Network Metrics'!AC10 -> B | B8: ='Default Network Metrics'!AD10 -> 5 | C8: ='Default Network Metrics'!AE10 -> 2
A9: ='Default Network Metrics'!AC11 -> B | B9: ='Event Register'!H2 -> 5 | C9: =MAX('Event Register'!H6,'Event Register'!H68) -> 5
A10: ='Default Network Metrics'!AC12 -> B | B10: ='Event Register'!H3 -> 5 | C10: ='Event Register'!H7 -> 2
A11: ='Default Network Metrics'!AC13 -> B | B11: ='Event Register'!H4 -> 5 | C11: ='Event Register'!H8 -> 2
A12: ='Default Network Metrics'!AC14 -> B | B12: ='Event Register'!H5 -> 5 | C12: ='Event Register'!H9 -> 2
A13: ='Event Register'!H69 -> B | B13: ='Event Register'!H72 -> 5 | C13: ='Event Register'!H75 -> 5
A14: ='Default Network Metrics'!AC16 -> D | B14: ='Default Network Metrics'!AD16 -> 80 | C14: ='Default Network Metrics'!AE16 -> 0
A15: ='Default Network Metrics'!AC17 -> D | B15: =MAX('Event Register'!H37,'Event Register'!H50) -> 0 | C15: ='Default Network Metrics'!AE17 -> 0
A16: ='Event Register'!H70 -> B | B16: ='Event Register'!H73 -> 5 | C16: ='Event Register'!H76 -> 5
A17: ='Default Network Metrics'!AC19 -> D | B17: ='Default Network Metrics'!AD19 -> 80 | C17: ='Default Network Metrics'!AE19 -> 0
